---
layout: post
title: 深入了解Spring的事务管理 
---

### 深入了解Spring的事务管理

Spring 的事务处理对于我们来说即带来了便利性，又因为他的黑盒性质，带来了使用和处理的不确定性，如果不能明白Spring事务管理的内在原理，那么迟早会出现一些
Spring事务管理的bug.

#### 业务背景

在新的跨境业务当中，我们需要同步业务的订单和订单对应的商品，由于上线很急，那样进行充分的单元测试。便带来了Spring事务的一个bug。
表结构(少部分)
```sql
CREATE TABLE `outbound_order` (
  `order_no` varchar(64) NOT NULL DEFAULT '''''' COMMENT '订单号/出货单id',
  `user_id` varchar(64) DEFAULT NULL COMMENT '用户',
  `order_status` int(2) DEFAULT NULL COMMENT '操作状态',
  UNIQUE KEY `order_no_unique_index` (`order_no`,`user_id`)
) ENGINE=InnoDB AUTO_INCREMENT=419 DEFAULT CHARSET=utf8 COMMENT='出货单'

CREATE TABLE `outbound_item` (
  `order_no` varchar(64) DEFAULT NULL COMMENT '订单',
  `ae_user_id` varchar(64) DEFAULT NULL COMMENT '用户',
  PRIMARY KEY (`id`)
) ENGINE=InnoDB AUTO_INCREMENT=440 DEFAULT CHARSET=utf8
```

在实际的定时任务中进行的处理如下

```java
    @Scheduled(cron = "0 0 */2 * * *")
    public void sync(){
        //-----查询用户
        //同步用户订单
        addInfo(xxxx);
    }

    @Transactional
    public void addInfo(List<Order> orderList) {
        //查询订单状态，获取订单商品入库
        //处理订单对应的商品
        List<Item> itemList = xxxx(orderList);
        //处理订单
        orderDao.addOrderList(orderList);
        itemDao.addItemList(itemList);
    }
```

按照预期是要么订单和订单商品同时同步入库，或者同时失败。但是实际却是订单入库，但是订单对应的商品入库失败。

那么究竟是什么问题，首先看日志，发现是有数据没有通过接口返回而抛出了异常，但是为什么订单插入了，一时间发现是事务没有处理，但是他的类名却是OrderTask$$Enchaner$$SpringByCglib说明
是进入了代理的，带着这一层去翻了以下源代码.

#### 原理分析

根据 `Spring#Aop` 的处理方式直接定位 `CglibAopProxy的DynamicAdvisedInterceptor#intercept` 可以看到如下代码

```java
    //expose-proxy = true,将proxy保存到ThreadLocal中
	if (this.advised.exposeProxy) {
	    // Make invocation available if necessary.
		oldProxy = AopContext.setCurrentProxy(proxy);
		setProxyContext = true;
    }
    //找到切面结合
    List<Object> chain = this.advised.getInterceptorsAndDynamicInterceptionAdvice(method, targetClass);
    Object retVal;
    //没有切面，直接使用target掉用，从而没有进入Spring的事务代码
    if (chain.isEmpty() && Modifier.isPublic(method.getModifiers())) {
	    Object[] argsToUse = AopProxyUtils.adaptArgumentsIfNecessary(method, args);
	    retVal = methodProxy.invoke(target, argsToUse);
    }else {
	    // We need to create a method invocation...
	    retVal = new CglibMethodInvocation(proxy, target, method, args, targetClass, chain, methodProxy).proceed();
    }
```

经过分析我们的 `sync()` 却是没有 `@Transactional` 注解，也就不存在 `aop` 切面了. 但是另一个疑问又出现了 `addInfo` 方法被 `@Transactional` 注解了啊
于是再次debug发现，这是 `this` 调用，根本就不是 `proxy 代理` 在调用，既然不是代理方法，那么肯定就不会进入aop的拦截当中了，既然如此肯定就没有事务处理了。

结合本次出现的事务故障，又结合几种出现的场景进行了分析.

场景1. 事务1同时调用2次dao方法，未发生异常

```java
     @Transactional
     public Integer doSomething(Integer key) {
         PerformData performData = new PerformData();
         performDataDao.addPerformData(performData);
         performDataDao.addPerformData(performData);
         return 1;
     }
```

场景2. 事务1调用一次dao方法，内部再调用一次this.inner，不抛出异常

```java
    @Transactional
    public Integer doSomething(Integer key) {
        PerformData performData = new PerformData();
        performDataDao.addPerformData(performData);
        this.inner(performData);
        return 1;
    }

    @Transactional(propagation = Propagation.REQUIRES_NEW)
    public void inner(performData) {
        performDataDao.addPerformData(performData);
    }
```

场景3. 场景同2，但是inner方法抛出异常且不处理

```java
    @Transactional
    public Integer doSomething(Integer key) {
        PerformData performData = new PerformData();
        performDataDao.addPerformData(performData);
        this.inner(performData);
        return 1;
    }

    @Transactional(propagation = Propagation.REQUIRES_NEW)
    public void inner(PerformData performData) {
        performDataDao.addPerformData(performData);
        //抛出异常
        throw new RuntimeException();
    }```

场景4. 场景同3,invoke方法被普获并且处理

```java
    @Transactional
    public Integer doSomething(Integer key) {
        PerformData performData = new PerformData();
        performDataDao.addPerformData(performData);
        try {
            this.inner(performData);
        }catch (Exception e){
            //不抛出去
        }
        return 1;
    }

    @Transactional(propagation = Propagation.REQUIRES_NEW)
    public void inner(PerformData performData) {
        performDataDao.addPerformData(performData);
        throw new RuntimeException();
    }
```

> `this` 调用，加不加 `@Transactional` 一样的，没有区别，都不会走代理，如何使内部方法的注解生效参见<aop:xx expose-proxy=true/>
> ((PerformDataServiceImpl)AopContext.currentProxy()).inner(performData);

场景1结果:2次插入成功，可以理解
场景2结果:2次插入成功，可以理解
场景3结果:2次插入失败，异常被Spring普获，随后回滚。
场景4接口:2次插入成功，异常被上级方法普获，但是没有抛出去，Spring普获不到，直接`commit`

Spring 事务回滚源代码参考 `TransactionAspectSupport#invokeWithinTransaction`

```java
	try {
	// This is an around advice: Invoke the next interceptor in the chain.
	// This will normally result in a target object being invoked.
	    retVal = invocation.proceedWithInvocation();
	}
	catch (Throwable ex) {
	// target invocation exception
	    completeTransactionAfterThrowing(txInfo, ex);//如果是RuntimeException|Error或者设定了RollbackFor就回滚，否则提交
		throw ex;//重新抛出
	}
```

#### 小结

在这次业务出现的一些bug中还是学到一些基础的东西没有掌握完全，尤其是Spring相关，都还是只是看到了表面。尤其是@Transactional的标注位置和事务的处理息息相关。
Service 和 Dao 类的设计也存在不合理，这种不合理在需要使用处理的时候会变的格外突出。
